<?xml version="1.0"?>
<robot name="Pan-Tilt">

  <!-- the model -->
  <link name="base_link">
    <visual>
      <origin rpy="0 0 0" xyz="0 0 0"/>
      <geometry>
        <mesh filename="file:/home/andrea/catkin_ws/src/ag_pan_tilt/meshes/Pan.stl" scale="0.001 0.001 0.001"/>
      </geometry>
      <material name="black">
        <color rgba="0.2 0.2 0.2 1"/>
      </material>
    </visual>
  </link>

  <joint name="pan" type="revolute">
    <parent link="base_link"/>
    <child link="F3"/>
    <origin xyz="0 0 0.03994" rpy="0 0 0" />
    <axis xyz="0 0 1" />
    <limit effort="300" velocity="0.1" lower="-1.60" upper="1.60" />
  </joint>

  <link name="F3">
    <visual>
      <origin rpy="0 0 3.14159" xyz="0 0 -0.03994"/>
      <geometry>
        <mesh filename="file:/home/andrea/catkin_ws/src/ag_pan_tilt/meshes/F3.stl" scale="0.001 0.001 0.001"/>
      </geometry>
      <material name="grey">
        <color rgba="0.85 0.85 0.85 1.0"/>
      </material>
    </visual>
  </link>

  <joint name="fixed_joint" type="fixed">
    <parent link="F3"/>
    <child link="tilt_link"/>
    <origin xyz="0 0 0" rpy="0 0 0" />
  </joint>

  <link name="tilt_link">
    <visual>
      <origin rpy="0 0 0" xyz="0 0 -0.03994"/>
      <geometry>
        <mesh filename="file:/home/andrea/catkin_ws/src/ag_pan_tilt/meshes/Tilt.stl" scale="0.001 0.001 0.001"/>
      </geometry>
      <material name="black">
      </material>
    </visual>
  </link>

  <joint name="tilt" type="revolute">
    <parent link="tilt_link"/>
    <child link="F2"/>
    <origin xyz="0 -0.0206 0.04155" rpy="0 0 3.14159" />
    <axis xyz="0 1 0" />
    <limit effort="300" velocity="0.1" lower="-1.60" upper="0.70" />
  </joint>

  <link name="F2">
    <visual>
      <origin rpy="0 0 3.14159" xyz="0 -0.0206 -0.08149"/>
      <geometry>
        <mesh filename="file:/home/andrea/catkin_ws/src/ag_pan_tilt/meshes/F2.stl" scale="0.001 0.001 0.001"/>
      </geometry>
      <material name="grey">
      </material>
    </visual>
  </link>

</robot>

